Workbook
Name Slicer_الحالة_الفنية: #N/A
Name Slicer_نوع_السيارة_تفصيلي: #N/A
Name STKB_CVD_destype_cache_desformat_xml: 'بيان بالآليات'!#REF!
Name STKB_CVD_destype_cache_desformat_xml: 'قاعدة البيانات'!#REF!
Name شعبة_ابحر: Table3[شعبة ابحر]
Name شعبة_ابحر: Table3[شعبة ابحر]
Name شعبة_الاسكان: Table3[شعبة الاسكان]
Name شعبة_الاسكان: Table3[شعبة الاسكان]
Name شعبة_البغدادية: Table3[شعبة البغدادية]
Name شعبة_البغدادية: Table3[شعبة البغدادية]
Name شعبة_الجامعة: Table3[شعبة الجامعة]
Name شعبة_الجامعة: Table3[شعبة الجامعة]
Name شعبة_الحمدانية: Table3[شعبة الحمدانية]
Name شعبة_الحمدانية: Table3[شعبة الحمدانية]
Name شعبة_الساحل_الجنوبي: Table3[شعبة الساحل الجنوبي]
Name شعبة_الساحل_الجنوبي: Table3[شعبة الساحل الجنوبي]
Name شعبة_السالمية: Table3[شعبة السالمية]
Name شعبة_السالمية: Table3[شعبة السالمية]
Name شعبة_الشاطئ: Table3[شعبة الشاطئ]
Name شعبة_الشاطئ: Table3[شعبة الشاطئ]
Name شعبة_الصناعية: Table3[شعبة الصناعية]
Name شعبة_الصناعية: Table3[شعبة الصناعية]
Name شعبة_العزيزية: Table3[شعبة العزيزية]
Name شعبة_العزيزية: Table3[شعبة العزيزية]
Name شعبة_المروة: Table3[شعبة المروة]
Name شعبة_المروة: Table3[شعبة المروة]
Name شعبة_خزام: Table3[شعبة خزام]
Name شعبة_خزام: Table3[شعبة خزام]
Name قسم_الاسناد_الاول_والثاني_والثالث: Table3[قسم الاسناد الاول والثاني والثالث]
Name قسم_الاسناد_الاول_والثاني_والثالث: Table3[قسم الاسناد الاول والثاني والثالث]
Name مركز_ثول_الخارجي: Table3[مركز ثول الخارجي]
Name مركز_ثول_الخارجي: Table3[مركز ثول الخارجي]
Name مقسم_طريقة_العرض_الجهة_تفصيلي__تنطيق_الاوراكل: #N/A
Name مقسم_طريقة_العرض_الجهة_عام: #N/A
Name مقسم_طريقة_العرض_اللون: #N/A
Name مقسم_طريقة_العرض_المركز: #N/A
Name مقسم_طريقة_العرض_الموديل: #N/A
Name مقسم_طريقة_العرض_الموقع_الالية_الحالي: #N/A
Name مقسم_طريقة_العرض_تاريخ_الإصلاح: #N/A
Name مقسم_طريقة_العرض_تاريخ_العطل: #N/A
Name مقسم_طريقة_العرض_جهة_العطل: #N/A
Name مقسم_طريقة_العرض_رقم_الشاصية: #N/A
Name مقسم_طريقة_العرض_رقم_اللوحة_كامل: #N/A
Name مقسم_طريقة_العرض_مدة_العطل__بالايام: #N/A
Name مقسم_طريقة_العرض_نوع_السيارة_عام: #N/A
Name مقسم_طريقة_العرض_نوع_العطل: #N/A
Name مقسم_طريقة_العرض_وصف_العطل: #N/A

Sheet ادخال البيانات
A1: ادخال بيانات الاليات
A2: رقم الصنف | B2: نوع السيارة تفصيلي | C2: رقم اللوحة كامل | D2: الموديل | E2: اللون | F2: نوع السيارة عام | G2: رقم الشاصية | H2: الجهة عام | I2: الجهة تفصيلي (تنطيق الاوراكل) | J2: الموقع الالية الحالي | K2: الحالة الفنية | L2: نوع العطل | M2: وصف العطل | N2: تاريخ العطل | O2: تاريخ الإصلاح | P2: جهة العطل | Q2: المركز | R2: ملاحظة
A3: 1101700010006 | B3: سيارة اطفاء وانقاذ مزدوجة كومندر | C3: ب د ب 8021 | D3: 2016 | E3: رسمية - اصفر | F3: سيارة اطفاء | G3: 54F2AA500GWE11383 | H3: الدفاع المدني/مديرية منطقة مكة المكرمة/الإدارة العامة للدفاع المدني بمحافظة جدة | I3: مركز الدفاع المدني بباب مكة | J3: شعبة البغدادية | K3: تم الاصلاح | L3: كهربائي | M3: عطل كهربائي | N3: 12-11-1447 | O3: 18-11-1447 | P3: شعبة البغدادية | Q3: مركز بلد 3 ( باب مكة )
A4: 1101700010006 | B4: سيارة اطفاء وانقاذ مزدوجة كومندر | C4: ب ب ق 2256 | D4: 2015 | E4: رسمية - اصفر | F4: سيارة اطفاء | G4: 54F2AA50XFWE11194 | H4: الدفاع المدني/مديرية منطقة مكة المكرمة/الإدارة العامة للدفاع المدني بمحافظة جدة | I4: مركز الدفاع المدني بالخاسكية | J4: شعبة خزام | K4: تم الاصلاح | O4: 3-11-1447 | P4: شعبة خزام | Q4: مركز خزام 2 ( مدائن الفهد )
A5: 1104700020001 | B5: سيارة اسعاف فان جمس | C5: ا ه ب 4029 | D5: 2012 | E5: رسمية - اصفر وابيض | F5: فان | G5: 1GTW78CG5C1197663 | H5: ادارة العمليات/الإدارة العامة للدفاع المدني بمحافظة جدة | I5: شعبة الدفاع المدني الميدانية بالجامعة | J5: شعبة الجامعة | K5: تم الاصلاح | M5: بطاريات | N5: 9-3-1447 | O5: 6-11-1447 | P5: شعبة الجامعة | Q5: مركز شرق 1 ( الجامعة )
A6: 1106700020003 | B6: وايت سكس مرسيدس بمضخه وقاذف | C6: ا ه س 8369 | D6: 2013 | E6: رسمية - اصفر | F6: صهريج سكس | G6: WDAKHAAA7DL766569 | H6: الدفاع المدني/مديرية منطقة مكة المكرمة/الإدارة العامة للدفاع المدني بمحافظة جدة | I6: مركز الدفاع المدني بالعزيزية | J6: شعبة العزيزية | K6: تم الاصلاح | L6: أخرى | M6: قفل البكرة + بواكم + حساس فحمة الفرامل+مكينة زجاج يسار | N6: 2-12-1447 | O6: 8-12-1447 | P6: شعبة العزيزية | Q6: مركز وسط 2 ( العزيزية )
A7: 1105700080001 | B7: سيارة انارة | C7: ا ل ط 6396 | D7: 2011 | E7: رسمية - اصفر | F7: اف 450 | G7: 1fdtf4hy5bec59128 | H7: ادارة العمليات/الإدارة العامة للدفاع المدني بمحافظة جدة | I7: قسم الدعم والإسناد الثالث | J7: مركز الدعم والاسناد الأول والثاني والثالث | K7: تم الاصلاح | L7: كهربائي | M7: التماس كهربائي في السيارة | N7: 9-2-1447 | O7: 19-11-1447 | P7: قسم الاسناد الاول والثاني والثالث
A8: 1106700010003 | B8: وايت عادي مرسيدس بمضخة وقاذف | C8: د ن ل 713 | D8: 1989 | E8: رسمية - اصفر | F8: صهريج عادي | G8: 40402055346001 | H8: ادارة العمليات/الإدارة العامة للدفاع المدني بمحافظة جدة | I8: قسم الدعم والإسناد الثاني | J8: مركز الدعم والاسناد الأول والثاني والثالث | K8: تم الاصلاح | O8: 20-9-1447 | P8: قسم الاسناد الاول والثاني والثالث
A9: 1204700030001 | B9: سيارة جيب شاص تويوتا رسمي | C9: ا ع ل 7710 | D9: 2010 | E9: رسمية - اصفر | F9: جيب بكب | G9: JTFLU73JXA4512736 | H9: ادارة العمليات/الإدارة العامة للدفاع المدني بمحافظة جدة | I9: شعبة الدفاع المدني الميدانية بالصناعية | J9: شعبة الصناعية | K9: تم الاصلاح | O9: 7-8-1447 | P9: شعبة الصناعية | Q9: مركز صناعية 1 ( الصناعية )
A10: 1101700010006 | B10: سيارة اطفاء وانقاذ مزدوجة كومندر | C10: ب ا د 8241 | D10: 2015 | E10: رسمية - اصفر | F10: سيارة اطفاء | G10: 54F2AA505FWE11054 | H10: الدفاع المدني/مديرية منطقة مكة المكرمة/الإدارة العامة للدفاع المدني بمحافظة جدة | I10: مركز الدفاع المدني بالخزام | J10: شعبة المروة | K10: تم الاصلاح | L10: حادث مروري | M10: حادث مروري | N10: 2-12-1445 | O10: 29-1-1448 | P10: شعبة المروة | Q10: مركز صفا 2 ( النزهة ) | R10: الجهة شعبة خزام
A11: 1106700010003 | B11: وايت عادي مرسيدس بمضخة وقاذف | C11: ر ص س 200 | D11: 1981 | E11: رسمية - اصفر | F11: صهريج عادي | G11: 34631154808228 | H11: الدفاع المدني/مديرية منطقة مكة المكرمة/الإدارة العامة للدفاع المدني بمحافظة جدة | I11: قسم الدعم والاسناد الأول | J11: مركز الدعم والاسناد الأول والثاني والثالث | K11: عطلانة | L11: مضخات | M11: مضخة وتجديد | N11: 8-4-1447 | P11: شعبة العزيزية | Q11: مركز وسط 5 ( الاندلس ) | R11: شعبة العزيزية
A12: 1303700010001 | B12: دراجة نارية ياماها 250 | C12: ص ا 661 | D12: 2010 | E12: رسمية - اخضر | F12: دراجة نارية | G12: JYA4TN00000014030 | H12: ادارة العمليات/الإدارة العامة للدفاع المدني بمحافظة جدة | I12: قسم الدعم والإسناد الأول | J12: مركز الدعم والاسناد الأول والثاني والثالث | K12: تم الاصلاح | O12: 3-8-1447 | P12: قسم الاسناد الاول والثاني والثالث
A13: 1101700010006 | B13: سيارة اطفاء كبيره روزنباور | C13: ا ص م 3537 | D13: 2006 | E13: رسمية - اصفر | F13: سيارة اطفاء | G13: 44KFT42846WZ20824 | H13: ادارة العمليات/الإدارة العامة للدفاع المدني بمحافظة جدة | I13: قسم الدعم والإسناد الثاني | J13: مركز الدعم والاسناد الأول والثاني والثالث | K13: عطلانة | L13: مضخات | M13: مفتاح المضخة | N13: 8-4-1447 | P13: قسم الاسناد الاول والثاني والثالث
A14: 1106700010010 | B14: وايت عادي اكتروس بمضخه وقاذف | C14: س ق ه 393 | D14: 2004 | E14: رسمية - اصفر | F14: صهريج سكس | G14: WDB9300131K913344 | H14: ادارة العمليات/الإدارة العامة للدفاع المدني بمحافظة جدة | I14: قسم الدعم والإسناد الثاني | J14: الصيانة المركزية | K14: عطلانة | L14: أخرى | M14: تهريب ديزل + وتهريب من المضخة | N14: 28-12-1447 | O14: 27-12-1447 | P14: قسم الاسناد الاول والثاني والثالث
A15: 1106700020003 | B15: وايت سكس مرسيدس بمضخه وقاذف | C15: ا و م 2858 | D15: 2014 | E15: رسمية - اصفر | F15: سيارة اطفاء | G15: WDAKHAAA4EL854870 | H15: الدفاع المدني/مديرية منطقة مكة المكرمة/الإدارة العامة للدفاع المدني بمحافظة جدة | I15: مركز الدفاع المدني بحي مشرفة | J15: شعبة الشاطئ | K15: تم الاصلاح | L15: ميكانيكي | M15: عطل في القير | N15: 18-11-1447 | O15: 3-12-1447 | P15: شعبة الشاطئ | Q15: مركز غرب 2 ( الخالدية )
A16: 1106700020010 | B16: وايت سكس اكتروس بمضخه وقاذف | C16: ا ر ا 7183 | D16: 2009 | E16: رسمية - اصفر | F16: صهريج سكس | G16: WDAKHCAB69L381015 | H16: ادارة العمليات/الإدارة العامة للدفاع المدني بمحافظة جدة | I16: قسم الدعم والإسناد الثالث | J16: شعبة الحمدانية | K16: عطلانة | L16: ميكانيكي | M16: لايقبل التعشيق | N16: 1-10-1447 | P16: شعبة الحمدانية | Q16: مركز شمال 1 ( الحمدانية )
A17: 1101700020004 | B17: سيارة اطفاء صغيرة فورد | C17: ا ر ل 1863 | D17: 2003 | E17: رسمية - اصفر | F17: سيارة اطفاء | G17: 1FDXW47P43EC54014 | H17: الدفاع المدني/مديرية منطقة مكة المكرمة/الإدارة العامة للدفاع المدني بمحافظة جدة | I17: مركز الدفاع المدني بحي البوادي | J17: الصيانة المركزية | K17: تحت إجراءات الرجيع | L17: كهربائي | M17: عطل في الكهرباء | N17: 8-2-1445 | P17: شعبة الاسكان | Q17: مركز اسكان 1 ( الاسكان الجنوبي ) | R17: بديل من الاسناد --خزام 2
A18: 1106700020003 | B18: وايت سكس مرسيدس بمضخه وقاذف | C18: ا ن ع 8503 | D18: 2013 | E18: رسمية - اصفر | F18: صهريج سكس | G18: WDAKHAAA3DL708264 | H18: الدفاع المدني/مديرية منطقة مكة المكرمة/الإدارة العامة للدفاع المدني بمحافظة جدة | I18: مركز الدفاع المدني بالشاطئ | J18: شعبة الشاطئ | K18: عطلانة | L18: أخرى | M18: عطل بلف الديزل الراجع | N18: 12-11-1447 | O18: 18-10-1447 | P18: شعبة الشاطئ | Q18: مركز غرب 1 ( الشاطئ )
A19: 1204700030001 | B19: سيارة جيب شاص تويوتا رسمي | C19: ا ص ط 4840 | D19: 2009 | E19: رسمية - اصفر | F19: جيب بكب | G19: jtflj71j698018387 | H19: ادارة العمليات/الإدارة العامة للدفاع المدني بمحافظة جدة | I19: قسم الدعم والإسناد الأول | J19: مركز الدعم والاسناد الأول والثاني والثالث | K19: عطلانة | L19: أخرى | M19: عطل في مفتاح البودرة | N19: 7-4-1445 | P19: قسم الاسناد الاول والثاني والثالث
A20: 1106700020003 | B20: وايت سكس مرسيدس بمضخه وقاذف | C20: ا و م 7674 | D20: 2014 | E20: رسمية - اصفر | F20: سيارة اطفاء | G20: WDAKHAAA5EL866669 | H20: الدفاع المدني/مديرية منطقة مكة المكرمة/الإدارة العامة للدفاع المدني بمحافظة جدة | I20: مركز الدفاع المدني بالخمرة | J20: شعبة الساحل الجنوبي | K20: عطلانة | L20: كهربائي | M20: خلل في الكهرباء | N20: 10-1-1448 | O20: 27-11-1447 | P20: شعبة الساحل الجنوبي | Q20: مركز جنوب 4 ( الخمرة )
A21: 1102700010004 | B21: سيارات انقاذ كبيرة فورد | C21: ا ن ط 2419 | D21: 2012 | E21: رسمية - اصفر | F21: اب اف 350 | G21: 1FD8W3H67CEB64487 | H21: الدفاع المدني/مديرية منطقة مكة المكرمة/الإدارة العامة للدفاع المدني بمحافظة جدة | I21: مركز الدفاع المدني بالنزهة | J21: شعبة المروة | K21: عطلانة | L21: أخرى | M21: تهريب في تانكي البنزين | N21: 26-1-1448 | O21: 25-12-1447 | P21: شعبة المروة | Q21: مركز صفا 2 ( النزهة )
A22: 1105700080001 | B22: سيارة انارة | C22: ب ا ق 1832 | D22: 2015 | E22: رسمية - اصفر | F22: اف 450 | G22: 1FDTF4HY5FEB64249 | H22: ادارة العمليات/الإدارة العامة للدفاع المدني بمحافظة جدة | I22: قسم الدعم والإسناد الثاني | J22: مركز الدعم والاسناد الأول والثاني والثالث | K22: تعمل بوجود ملاحظات | L22: كهربائي | M22: عطل حساس القير | N22: 6-4-1446 | P22: قسم الاسناد الاول والثاني والثالث
A23: 1106700020003 | B23: وايت سكس مرسيدس بمضخه وقاذف | C23: أ ن ط 2502 | D23: 2013 | E23: رسمية - اصفر | F23: صهريج سكس | G23: WDAKHAAA6DL716861 | H23: ادارة العمليات/الإدارة العامة للدفاع المدني بمحافظة جدة | I23: قسم الدعم والإسناد الثالث | J23: مركز الدعم والاسناد الأول والثاني والثالث | K23: تم الاصلاح | L23: ميكانيكي | M23: بواكم الهواء | N23: 6-2-1447 | O23: 30-11-1447 | P23: قسم الاسناد الاول والثاني والثالث
A24: 1204700010003 | B24: سيارة جيب 2 باب نيسان رسمي | C24: ا ل ع 1091 | D24: 2009 | E24: رسمية - اصفر | F24: جيب | G24: JN8BY14YX9X539595 | H24: ادارة العمليات/الإدارة العامة للدفاع المدني بمحافظة جدة | I24: شعبة الدفاع المدني الميدانية بالحمدانية | J24: شعبة الحمدانية | K24: عطلانة | L24: أخرى | M24: ارتفاع درجة الحرارة | N24: 5-8-1446 | P24: شعبة الحمدانية | Q24: مركز شمال 1 ( الحمدانية ) | R24: بديل من الشعبة
A25: 1106700020003 | B25: وايت سكس مرسيدس بمضخه وقاذف | C25: ا ص م 3618 | D25: 1983 | E25: رسمية - اصفر | F25: صهريج سكس | G25: 3430154805270 | H25: الدفاع المدني/مديرية منطقة مكة المكرمة/الإدارة العامة للدفاع المدني بمحافظة جدة | I25: مركز الدفاع المدني بالاسواق الشعبية | J25: شعبة الصناعية | K25: تم الاصلاح | L25: ميكانيكي | M25: عطل في القير | N25: 5-8-1446 | O25: 24-1-1448 | P25: شعبة الصناعية | Q25: مركز صناعية 3 ( الاسواق الشعبية ) | R25: يوجد بديل من الشعبة
A26: 1102700010004 | B26: سيارات انقاذ كبيرة فورد | C26: ا ح ع 3209 | D26: 2008 | E26: رسمية - اصفر | F26: شاحنة | G26: 1FDWW37Y58EB05374 | H26: ادارة العمليات/الإدارة العامة للدفاع المدني بمحافظة جدة | I26: قسم الدعم والإسناد الثاني | J26: مركز الدعم والاسناد الأول والثاني والثالث | K26: عطلانة | L26: أخرى | M26: الادراج +السفتي +الونان+الفرامل | N26: 5-8-1444 | P26: قسم الاسناد الاول والثاني والثالث
A27: 1105700010001 | B27: سيارة سلالم 28 متر | C27: ا ك ع 1641 | D27: 2006 | E27: رسمية - اصفر | F27: رافعة تلسكوبيه | G27: WJMAIVRM004312280 | H27: ادارة العمليات/الإدارة العامة للدفاع المدني بمحافظة جدة | I27: قسم الدعم والإسناد الثاني | J27: مركز الدعم والاسناد الأول والثاني والثالث | K27: تم الاصلاح | L27: أخرى | M27: اعطال متعدده | N27: 2-1-1448 | O27: 15-1-1448 | P27: شعبة الشاطئ | Q27: مركز غرب 1 ( الشاطئ ) | R27: ( سلالم الطائف)
A28: 1106700020003 | B28: وايت سكس مرسيدس بمضخه وقاذف | C28: أ د م 4920 | D28: 2003 | E28: رسمية - اصفر | F28: صهريج سكس | G28: WDB9500135K765118 | H28: ادارة العمليات/الإدارة العامة للدفاع المدني بمحافظة جدة | I28: قسم الدعم والإسناد الثالث | J28: مركز الدعم والاسناد الأول والثاني والثالث | K28: عطلانة | L28: خلل فني | M28: عصا القير وتنسيم هواء من احد الخزانات | N28: 24-8-1447 | P28: قسم الاسناد الاول والثاني والثالث
A29: 1104700010001 | B29: سيارة اسعاف صالون جمس | C29: ب ل ص 9475 | D29: 2005 | E29: رسمية - اصفر | F29: صالون | G29: 3GKFK16T05G272258 | H29: ادارة العمليات/الإدارة العامة للدفاع المدني بمحافظة جدة | I29: شعبة الدفاع المدني الميدانية بالإسكان الجنوبي | J29: شعبة الإسكان الجنوبي | K29: تم الاصلاح | M29: بطاريات | N29: 4-5-1447 | O29: 5-11-1447 | P29: شعبة الاسكان | Q29: مركز اسكان 1 ( الاسكان الجنوبي )
A30: 1106700020003 | B30: وايت سكس مرسيدس بمضخه وقاذف | C30: أ ن ب 3894 | D30: 2013 | E30: رسمية - اصفر | F30: صهريج سكس | G30: WDAKHAAA2DL713777 | H30: ادارة العمليات/الإدارة العامة للدفاع المدني بمحافظة جدة | I30: قسم الدعم والإسناد الثاني | J30: شعبة الحمدانية | K30: عطلانة | L30: أخرى | M30: كسر في الفلتر والرفرف | N30: 4-3-1447 | P30: شعبة الحمدانية | Q30: مركز شمال 5 ( ذهبان ) | R30: الاسناد
A31: 1207700040006 | B31: سيارة رآس تريلا سكس مان | C31: ا ن د 4774 | D31: 2013 | E31: رسمية - اصفر | F31: تريلا | G31: WMA26WZZ6DM613818 | H31: ادارة العمليات/الإدارة العامة للدفاع المدني بمحافظة جدة | I31: قسم الدعم والإسناد الثاني | J31: مركز الدعم والاسناد الأول والثاني والثالث | K31: عطلانة | L31: ميكانيكي | M31: تهريب هواء من الباكم (الفرامل) | N31: 1-12-1447 | O31: 10-11-1447 | P31: قسم الاسناد الاول والثاني والثالث
A32: 1204700010003 | B32: سيارة جيب 2 باب نيسان رسمي | C32: ا م ط 6540 | D32: 2006 | E32: رسمية - اصفر | F32: جيب | G32: JN8BY14Y06X525619 | H32: ادارة العمليات/الإدارة العامة للدفاع المدني بمحافظة جدة | I32: شعبة الدفاع المدني الميدانية بالإسكان الجنوبي | J32: شعبة الإسكان الجنوبي | K32: عطلانة | L32: ميكانيكي | M32: تهريب في ماء الرديتر | N32: 3-9-1446 | P32: شعبة الاسكان | Q32: مركز اسكان 1 ( الاسكان الجنوبي )
A33: 1106700010003 | B33: وايت عادي مرسيدس بمضخة وقاذف | C33: ا د م 2203 | D33: 1989 | E33: رسمية - اصفر | F33: صهريج عادي | G33: 34600155410132 | H33: ادارة العمليات/الإدارة العامة للدفاع المدني بمحافظة جدة | I33: شعبة الدفاع المدني الميدانية بالمروة | J33: شعبة المروة | K33: تم الاصلاح | L33: خلل فني | M33: تهريب هواء وثقل بالفرامل | N33: 22-9-1447 | O33: 17-1-1448 | P33: شعبة الحمدانية | Q33: مركز شمال 3 ( الرحيلي )
A34: 1201700020002 | B34: وايت ماء سقيا سكس مان | C34: ا ى ن 3852 | D34: 2015 | E34: رسمية - اصفر | F34: صهريج سكس (32) م2 | G34: RS076WZZXFD008481 | H34: ادارة العمليات/الإدارة العامة للدفاع المدني بمحافظة جدة | I34: قسم الدعم والإسناد الثالث | J34: شعبة أبحر | K34: عطلانة | L34: أخرى | M34: تهريب بلف الغطاس | N34: 3-4-1446 | P34: شعبة ابحر | Q34: مركز ابحر 1 ( ابحر الجنوبية ) | R34: الاسناد
A35: 1204700010003 | B35: سيارة جيب 2 باب نيسان رسمي | C35: ا ل ع 1060 | D35: 2009 | E35: رسمية - اصفر | F35: جيب | G35: JN8BY14Y29X539588 | H35: ادارة العمليات/الإدارة العامة للدفاع المدني بمحافظة جدة | I35: شعبة الدفاع المدني الميدانية بالشاطئ | J35: شعبة الشاطئ | K35: تم الاصلاح | O35: 6-8-1447 | P35: شعبة الشاطئ | Q35: مركز غرب 1 ( الشاطئ )
A36: 1106700020003 | B36: وايت سكس مرسيدس بمضخه وقاذف | C36: ا ه س 6583 | D36: 2013 | E36: رسمية - اصفر | F36: صهريج سكس | G36: WDAKHAAA3DL772417 | H36: الدفاع المدني/مديرية منطقة مكة المكرمة/الإدارة العامة للدفاع المدني بمحافظة جدة | I36: مركز الدفاع المدني بالربوة | J36: شعبة المروة | K36: تم الاصلاح | O36: 13-8-1447 | P36: شعبة المروة | Q36: مركز صفا 3 ( الربوة )
A37: 1105700100001 | B37: سيارة فان افيكو رسمي للتجهيزات الفنية لوحدة الغواصين | C37: ب ا ح 2731 | D37: 2015 | E37: رسمية - اصفر | F37: فان | G37: ZCFC50AY6FD540305 | H37: ادارة العمليات/الإدارة العامة للدفاع المدني بمحافظة جدة | I37: قسم الدعم والإسناد الثالث | J37: شعبة البغدادية | K37: تم الاصلاح | O37: 13-8-1447 | P37: شعبة البغدادية | Q37: مركز بلد 1 ( الحمراء )
A38: 1106700020003 | B38: وايت سكس مرسيدس بمضخه وقاذف | C38: ا ن ط 2479 | D38: 2013 | E38: رسمية - اصفر | F38: صهريج سكس | G38: WDAKHAAA9DL719091 | H38: الدفاع المدني/مديرية منطقة مكة المكرمة/الإدارة العامة للدفاع المدني بمحافظة جدة | I38: مركز الدفاع المدني بالمروة | J38: شعبة المروة | K38: تم الاصلاح | L38: ميكانيكي | M38: تهريب هواء | N38: 30-3-1447 | O38: 22-1-1448 | P38: شعبة المروة | Q38: مركز صفا 5 ( الفيصلية )
A39: 1104700020001 | B39: سيارة اسعاف فان جمس | C39: ا ه ب 4251 | D39: 2012 | E39: رسمية - اصفر وابيض | F39: فان | G39: 1GTW78CG0C1193679 | H39: ادارة العمليات/الإدارة العامة للدفاع المدني بمحافظة جدة | I39: شعبة الدفاع المدني الميدانية بالعزيزية | J39: شعبة العزيزية | K39: عطلانة | L39: كهربائي | M39: التماس كهربائي في الكابينة | N39: 30-1-1447 | P39: شعبة العزيزية | Q39: مركز وسط 1 ( الرحاب )
A40: 1102700010004 | B40: سيارات انقاذ كبيرة فورد | C40: ا ص م 3845 | D40: 2010 | E40: رسمية - اصفر | F40: شاحنة | G40: 1FDWW3HY6AEA69487 | H40: ادارة العمليات/الإدارة العامة للدفاع المدني بمحافظة جدة | I40: قسم الدعم والإسناد الأول | J40: مركز الدعم والاسناد الأول والثاني والثالث | K40: عطلانة | L40: كهربائي | M40: عطل في السلف | N40: 21-1-1448 | O40: 20-1-1448 | P40: شعبة العزيزية | Q40: مركز وسط 2 ( العزيزية )
...

Sheet لوحة التحكم
A9: السنة | B9: الكل | C9: جدول احصائي لحالة المركبات
A10: الشهر | B10: الكل
A11: الاسبوع | B11: الكل
A12: رقم الصنف | B12: نوع السيارة تفصيلي | C12: رقم اللوحة كامل | D12: الموديل | E12: اللون | F12: نوع السيارة عام | G12: رقم الشاصية | H12: الجهة عام | I12: الجهة تفصيلي (تنطيق الاوراكل) | J12: الموقع الالية الحالي | K12: الحالة الفنية | L12: نوع العطل | M12: وصف العطل | N12: تاريخ العطل | O12: تاريخ الإصلاح | P12: جهة العطل | Q12: المركز | R12: ملاحظة | S12: مدة العطل (بالايام)
A13: 1101700010006 | B13: سيارة اطفاء وانقاذ مزدوجة كومندر | C13: ب د ب 8021 | D13: 2016 | E13: رسمية - اصفر | F13: سيارة اطفاء | G13: 54F2AA500GWE11383 | H13: الدفاع المدني/مديرية منطقة مكة المكرمة/الإدارة العامة للدفاع المدني بمحافظة جدة | I13: مركز الدفاع المدني بباب مكة | J13: شعبة البغدادية | K13: تم الاصلاح | L13: كهربائي | M13: عطل كهربائي | N13: 12-11-1447 | O13: 18-11-1447 | P13: شعبة البغدادية | Q13: مركز بلد 3 ( باب مكة ) | S13: =IF( OR(K13="تم الاصلاح", O13<>""), "تم الاصلاح", IF(N13="", "", TODAY()-N13) ) -> تم الاصلاح
A14: 1101700010006 | B14: سيارة اطفاء وانقاذ مزدوجة كومندر | C14: ب ب ق 2256 | D14: 2015 | E14: رسمية - اصفر | F14: سيارة اطفاء | G14: 54F2AA50XFWE11194 | H14: الدفاع المدني/مديرية منطقة مكة المكرمة/الإدارة العامة للدفاع المدني بمحافظة جدة | I14: مركز الدفاع المدني بالخاسكية | J14: شعبة خزام | K14: تم الاصلاح | O14: 3-11-1447 | P14: شعبة خزام | Q14: مركز خزام 2 ( مدائن الفهد ) | R14: لايوجد بديل | S14: =IF( OR(K14="تم الاصلاح", O14<>""), "تم الاصلاح", IF(N14="", "", TODAY()-N14) ) -> تم الاصلاح
A15: 1104700020001 | B15: سيارة اسعاف فان جمس | C15: ا ه ب 4029 | D15: 2012 | E15: رسمية - اصفر وابيض | F15: فان | G15: 1GTW78CG5C1197663 | H15: ادارة العمليات/الإدارة العامة للدفاع المدني بمحافظة جدة | I15: شعبة الدفاع المدني الميدانية بالجامعة | J15: شعبة الجامعة | K15: تم الاصلاح | M15: بطاريات | N15: 9-3-1447 | O15: 6-11-1447 | P15: شعبة الجامعة | Q15: مركز شرق 1 ( الجامعة ) | S15: =IF( OR(K15="تم الاصلاح", O15<>""), "تم الاصلاح", IF(N15="", "", TODAY()-N15) ) -> تم الاصلاح
A16: 1106700020003 | B16: وايت سكس مرسيدس بمضخه وقاذف | C16: ا ه س 8369 | D16: 2013 | E16: رسمية - اصفر | F16: صهريج سكس | G16: WDAKHAAA7DL766569 | H16: الدفاع المدني/مديرية منطقة مكة المكرمة/الإدارة العامة للدفاع المدني بمحافظة جدة | I16: مركز الدفاع المدني بالعزيزية | J16: شعبة العزيزية | K16: تم الاصلاح | L16: أخرى | M16: قفل البكرة + بواكم + حساس فحمة الفرامل+مكينة زجاج يسار | N16: 2-12-1447 | O16: 8-12-1447 | P16: شعبة العزيزية | Q16: مركز وسط 2 ( العزيزية ) | S16: =IF( OR(K16="تم الاصلاح", O16<>""), "تم الاصلاح", IF(N16="", "", TODAY()-N16) ) -> تم الاصلاح
A17: 1105700080001 | B17: سيارة انارة | C17: ا ل ط 6396 | D17: 2011 | E17: رسمية - اصفر | F17: اف 450 | G17: 1fdtf4hy5bec59128 | H17: ادارة العمليات/الإدارة العامة للدفاع المدني بمحافظة جدة | I17: قسم الدعم والإسناد الثالث | J17: مركز الدعم والاسناد الأول والثاني والثالث | K17: تم الاصلاح | L17: كهربائي | M17: التماس كهربائي في السيارة | N17: 9-2-1447 | O17: 19-11-1447 | P17: قسم الاسناد الاول والثاني والثالث | S17: =IF( OR(K17="تم الاصلاح", O17<>""), "تم الاصلاح", IF(N17="", "", TODAY()-N17) ) -> تم الاصلاح
A18: 1106700010003 | B18: وايت عادي مرسيدس بمضخة وقاذف | C18: د ن ل 713 | D18: 1989 | E18: رسمية - اصفر | F18: صهريج عادي | G18: 40402055346001 | H18: ادارة العمليات/الإدارة العامة للدفاع المدني بمحافظة جدة | I18: قسم الدعم والإسناد الثاني | J18: مركز الدعم والاسناد الأول والثاني والثالث | K18: تم الاصلاح | O18: 20-9-1447 | P18: قسم الاسناد الاول والثاني والثالث | S18: =IF( OR(K18="تم الاصلاح", O18<>""), "تم الاصلاح", IF(N18="", "", TODAY()-N18) ) -> تم الاصلاح
A19: 1204700030001 | B19: سيارة جيب شاص تويوتا رسمي | C19: ا ع ل 7710 | D19: 2010 | E19: رسمية - اصفر | F19: جيب بكب | G19: JTFLU73JXA4512736 | H19: ادارة العمليات/الإدارة العامة للدفاع المدني بمحافظة جدة | I19: شعبة الدفاع المدني الميدانية بالصناعية | J19: شعبة الصناعية | K19: تم الاصلاح | O19: 7-8-1447 | P19: شعبة الصناعية | Q19: مركز صناعية 1 ( الصناعية ) | S19: =IF( OR(K19="تم الاصلاح", O19<>""), "تم الاصلاح", IF(N19="", "", TODAY()-N19) ) -> تم الاصلاح
A20: 1101700010006 | B20: سيارة اطفاء وانقاذ مزدوجة كومندر | C20: ب ا د 8241 | D20: 2015 | E20: رسمية - اصفر | F20: سيارة اطفاء | G20: 54F2AA505FWE11054 | H20: الدفاع المدني/مديرية منطقة مكة المكرمة/الإدارة العامة للدفاع المدني بمحافظة جدة | I20: مركز الدفاع المدني بالخزام | J20: شعبة المروة | K20: تم الاصلاح | L20: حادث مروري | M20: حادث مروري | N20: 2-12-1445 | O20: 29-1-1448 | P20: شعبة المروة | Q20: مركز صفا 2 ( النزهة ) | R20: الجهة شعبة خزام | S20: =IF( OR(K20="تم الاصلاح", O20<>""), "تم الاصلاح", IF(N20="", "", TODAY()-N20) ) -> تم الاصلاح
A21: 1106700010003 | B21: وايت عادي مرسيدس بمضخة وقاذف | C21: ر ص س 200 | D21: 1981 | E21: رسمية - اصفر | F21: صهريج عادي | G21: 34631154808228 | H21: الدفاع المدني/مديرية منطقة مكة المكرمة/الإدارة العامة للدفاع المدني بمحافظة جدة | I21: قسم الدعم والاسناد الأول | J21: مركز الدعم والاسناد الأول والثاني والثالث | K21: عطلانة | L21: مضخات | M21: مضخة وتجديد | N21: 8-4-1447 | P21: شعبة العزيزية | Q21: مركز وسط 5 ( الاندلس ) | R21: شعبة العزيزية | S21: =IF( OR(K21="تم الاصلاح", O21<>""), "تم الاصلاح", IF(N21="", "", TODAY()-N21) ) -> #VALUE!
A22: 1303700010001 | B22: دراجة نارية ياماها 250 | C22: ص ا 661 | D22: 2010 | E22: رسمية - اخضر | F22: دراجة نارية | G22: JYA4TN00000014030 | H22: ادارة العمليات/الإدارة العامة للدفاع المدني بمحافظة جدة | I22: قسم الدعم والإسناد الأول | J22: مركز الدعم والاسناد الأول والثاني والثالث | K22: تم الاصلاح | O22: 3-8-1447 | P22: قسم الاسناد الاول والثاني والثالث | S22: =IF( OR(K22="تم الاصلاح", O22<>""), "تم الاصلاح", IF(N22="", "", TODAY()-N22) ) -> تم الاصلاح
A23: 1101700010006 | B23: سيارة اطفاء كبيره روزنباور | C23: ا ص م 3537 | D23: 2006 | E23: رسمية - اصفر | F23: سيارة اطفاء | G23: 44KFT42846WZ20824 | H23: ادارة العمليات/الإدارة العامة للدفاع المدني بمحافظة جدة | I23: قسم الدعم والإسناد الثاني | J23: مركز الدعم والاسناد الأول والثاني والثالث | K23: عطلانة | L23: مضخات | M23: مفتاح المضخة | N23: 8-4-1447 | P23: قسم الاسناد الاول والثاني والثالث | S23: =IF( OR(K23="تم الاصلاح", O23<>""), "تم الاصلاح", IF(N23="", "", TODAY()-N23) ) -> #VALUE!
A24: 1106700010010 | B24: وايت عادي اكتروس بمضخه وقاذف | C24: س ق ه 393 | D24: 2004 | E24: رسمية - اصفر | F24: صهريج سكس | G24: WDB9300131K913344 | H24: ادارة العمليات/الإدارة العامة للدفاع المدني بمحافظة جدة | I24: قسم الدعم والإسناد الثاني | J24: الصيانة المركزية | K24: عطلانة | L24: أخرى | M24: تهريب ديزل + وتهريب من المضخة | N24: 28-12-1447 | O24: 27-12-1447 | P24: قسم الاسناد الاول والثاني والثالث | S24: =IF( OR(K24="تم الاصلاح", O24<>""), "تم الاصلاح", IF(N24="", "", TODAY()-N24) ) -> تم الاصلاح
A25: 1106700020003 | B25: وايت سكس مرسيدس بمضخه وقاذف | C25: ا و م 2858 | D25: 2014 | E25: رسمية - اصفر | F25: سيارة اطفاء | G25: WDAKHAAA4EL854870 | H25: الدفاع المدني/مديرية منطقة مكة المكرمة/الإدارة العامة للدفاع المدني بمحافظة جدة | I25: مركز الدفاع المدني بحي مشرفة | J25: شعبة الشاطئ | K25: تم الاصلاح | L25: ميكانيكي | M25: عطل في القير | N25: 18-11-1447 | O25: 3-12-1447 | P25: شعبة الشاطئ | Q25: مركز غرب 2 ( الخالدية ) | S25: =IF( OR(K25="تم الاصلاح", O25<>""), "تم الاصلاح", IF(N25="", "", TODAY()-N25) ) -> تم الاصلاح
A26: 1106700020010 | B26: وايت سكس اكتروس بمضخه وقاذف | C26: ا ر ا 7183 | D26: 2009 | E26: رسمية - اصفر | F26: صهريج سكس | G26: WDAKHCAB69L381015 | H26: ادارة العمليات/الإدارة العامة للدفاع المدني بمحافظة جدة | I26: قسم الدعم والإسناد الثالث | J26: شعبة الحمدانية | K26: عطلانة | L26: ميكانيكي | M26: لايقبل التعشيق | N26: 1-10-1447 | P26: شعبة الحمدانية | Q26: مركز شمال 1 ( الحمدانية ) | S26: =IF( OR(K26="تم الاصلاح", O26<>""), "تم الاصلاح", IF(N26="", "", TODAY()-N26) ) -> #VALUE!
A27: 1101700020004 | B27: سيارة اطفاء صغيرة فورد | C27: ا ر ل 1863 | D27: 2003 | E27: رسمية - اصفر | F27: سيارة اطفاء | G27: 1FDXW47P43EC54014 | H27: الدفاع المدني/مديرية منطقة مكة المكرمة/الإدارة العامة للدفاع المدني بمحافظة جدة | I27: مركز الدفاع المدني بحي البوادي | J27: الصيانة المركزية | K27: تحت إجراءات الرجيع | L27: كهربائي | M27: عطل في الكهرباء | N27: 8-2-1445 | P27: شعبة الاسكان | Q27: مركز اسكان 1 ( الاسكان الجنوبي ) | R27: بديل من الاسناد --خزام 2 | S27: =IF( OR(K27="تم الاصلاح", O27<>""), "تم الاصلاح", IF(N27="", "", TODAY()-N27) ) -> #VALUE!
A28: 1204700030001 | B28: سيارة جيب شاص تويوتا رسمي | C28: ا ص ط 4840 | D28: 2009 | E28: رسمية - اصفر | F28: جيب بكب | G28: jtflj71j698018387 | H28: ادارة العمليات/الإدارة العامة للدفاع المدني بمحافظة جدة | I28: قسم الدعم والإسناد الأول | J28: مركز الدعم والاسناد الأول والثاني والثالث | K28: عطلانة | L28: أخرى | M28: عطل في مفتاح البودرة | N28: 7-4-1445 | P28: قسم الاسناد الاول والثاني والثالث | S28: =IF( OR(K28="تم الاصلاح", O28<>""), "تم الاصلاح", IF(N28="", "", TODAY()-N28) ) -> #VALUE!
A29: 1106700020003 | B29: وايت سكس مرسيدس بمضخه وقاذف | C29: ا و م 7674 | D29: 2014 | E29: رسمية - اصفر | F29: سيارة اطفاء | G29: WDAKHAAA5EL866669 | H29: الدفاع المدني/مديرية منطقة مكة المكرمة/الإدارة العامة للدفاع المدني بمحافظة جدة | I29: مركز الدفاع المدني بالخمرة | J29: شعبة الساحل الجنوبي | K29: عطلانة | L29: كهربائي | M29: خلل في الكهرباء | N29: 10-1-1448 | O29: 27-11-1447 | P29: شعبة الساحل الجنوبي | Q29: مركز جنوب 4 ( الخمرة ) | S29: =IF( OR(K29="تم الاصلاح", O29<>""), "تم الاصلاح", IF(N29="", "", TODAY()-N29) ) -> تم الاصلاح
A30: 1102700010004 | B30: سيارات انقاذ كبيرة فورد | C30: ا ن ط 2419 | D30: 2012 | E30: رسمية - اصفر | F30: اب اف 350 | G30: 1FD8W3H67CEB64487 | H30: الدفاع المدني/مديرية منطقة مكة المكرمة/الإدارة العامة للدفاع المدني بمحافظة جدة | I30: مركز الدفاع المدني بالنزهة | J30: شعبة المروة | K30: عطلانة | L30: أخرى | M30: تهريب في تانكي البنزين | N30: 26-1-1448 | O30: 25-12-1447 | P30: شعبة المروة | Q30: مركز صفا 2 ( النزهة ) | S30: =IF( OR(K30="تم الاصلاح", O30<>""), "تم الاصلاح", IF(N30="", "", TODAY()-N30) ) -> تم الاصلاح
A31: 1105700080001 | B31: سيارة انارة | C31: ب ا ق 1832 | D31: 2015 | E31: رسمية - اصفر | F31: اف 450 | G31: 1FDTF4HY5FEB64249 | H31: ادارة العمليات/الإدارة العامة للدفاع المدني بمحافظة جدة | I31: قسم الدعم والإسناد الثاني | J31: مركز الدعم والاسناد الأول والثاني والثالث | K31: تعمل بوجود ملاحظات | L31: كهربائي | M31: عطل حساس القير | N31: 6-4-1446 | P31: قسم الاسناد الاول والثاني والثالث | S31: =IF( OR(K31="تم الاصلاح", O31<>""), "تم الاصلاح", IF(N31="", "", TODAY()-N31) ) -> #VALUE!
A32: 1106700020003 | B32: وايت سكس مرسيدس بمضخه وقاذف | C32: أ ن ط 2502 | D32: 2013 | E32: رسمية - اصفر | F32: صهريج سكس | G32: WDAKHAAA6DL716861 | H32: ادارة العمليات/الإدارة العامة للدفاع المدني بمحافظة جدة | I32: قسم الدعم والإسناد الثالث | J32: مركز الدعم والاسناد الأول والثاني والثالث | K32: تم الاصلاح | L32: ميكانيكي | M32: بواكم الهواء | N32: 6-2-1447 | O32: 30-11-1447 | P32: قسم الاسناد الاول والثاني والثالث | S32: =IF( OR(K32="تم الاصلاح", O32<>""), "تم الاصلاح", IF(N32="", "", TODAY()-N32) ) -> تم الاصلاح
A33: 1204700010003 | B33: سيارة جيب 2 باب نيسان رسمي | C33: ا ل ع 1091 | D33: 2009 | E33: رسمية - اصفر | F33: جيب | G33: JN8BY14YX9X539595 | H33: ادارة العمليات/الإدارة العامة للدفاع المدني بمحافظة جدة | I33: شعبة الدفاع المدني الميدانية بالحمدانية | J33: شعبة الحمدانية | K33: عطلانة | L33: أخرى | M33: ارتفاع درجة الحرارة | N33: 5-8-1446 | P33: شعبة الحمدانية | Q33: مركز شمال 1 ( الحمدانية ) | R33: بديل من الشعبة | S33: =IF( OR(K33="تم الاصلاح", O33<>""), "تم الاصلاح", IF(N33="", "", TODAY()-N33) ) -> #VALUE!
A34: 1106700020003 | B34: وايت سكس مرسيدس بمضخه وقاذف | C34: ا ص م 3618 | D34: 1983 | E34: رسمية - اصفر | F34: صهريج سكس | G34: 3430154805270 | H34: الدفاع المدني/مديرية منطقة مكة المكرمة/الإدارة العامة للدفاع المدني بمحافظة جدة | I34: مركز الدفاع المدني بالاسواق الشعبية | J34: شعبة الصناعية | K34: تم الاصلاح | L34: ميكانيكي | M34: عطل في القير | N34: 5-8-1446 | O34: 24-1-1448 | P34: شعبة الصناعية | Q34: مركز صناعية 3 ( الاسواق الشعبية ) | R34: يوجد بديل من الشعبة | S34: =IF( OR(K34="تم الاصلاح", O34<>""), "تم الاصلاح", IF(N34="", "", TODAY()-N34) ) -> تم الاصلاح
A35: 1102700010004 | B35: سيارات انقاذ كبيرة فورد | C35: ا ح ع 3209 | D35: 2008 | E35: رسمية - اصفر | F35: شاحنة | G35: 1FDWW37Y58EB05374 | H35: ادارة العمليات/الإدارة العامة للدفاع المدني بمحافظة جدة | I35: قسم الدعم والإسناد الثاني | J35: مركز الدعم والاسناد الأول والثاني والثالث | K35: عطلانة | L35: أخرى | M35: الادراج +السفتي +الونان+الفرامل | N35: 5-8-1444 | P35: قسم الاسناد الاول والثاني والثالث | S35: =IF( OR(K35="تم الاصلاح", O35<>""), "تم الاصلاح", IF(N35="", "", TODAY()-N35) ) -> #VALUE!
A36: 1105700010001 | B36: سيارة سلالم 28 متر | C36: ا ك ع 1641 | D36: 2006 | E36: رسمية - اصفر | F36: رافعة تلسكوبيه | G36: WJMAIVRM004312280 | H36: ادارة العمليات/الإدارة العامة للدفاع المدني بمحافظة جدة | I36: قسم الدعم والإسناد الثاني | J36: مركز الدعم والاسناد الأول والثاني والثالث | K36: تم الاصلاح | L36: أخرى | M36: اعطال متعدده | N36: 2-1-1448 | O36: 15-1-1448 | P36: شعبة الشاطئ | Q36: مركز غرب 1 ( الشاطئ ) | R36: ( سلالم الطائف) | S36: =IF( OR(K36="تم الاصلاح", O36<>""), "تم الاصلاح", IF(N36="", "", TODAY()-N36) ) -> تم الاصلاح
A37: 1106700020003 | B37: وايت سكس مرسيدس بمضخه وقاذف | C37: أ د م 4920 | D37: 2003 | E37: رسمية - اصفر | F37: صهريج سكس | G37: WDB9500135K765118 | H37: ادارة العمليات/الإدارة العامة للدفاع المدني بمحافظة جدة | I37: قسم الدعم والإسناد الثالث | J37: مركز الدعم والاسناد الأول والثاني والثالث | K37: عطلانة | L37: خلل فني | M37: عصا القير وتنسيم هواء من احد الخزانات | N37: 24-8-1447 | P37: قسم الاسناد الاول والثاني والثالث | S37: =IF( OR(K37="تم الاصلاح", O37<>""), "تم الاصلاح", IF(N37="", "", TODAY()-N37) ) -> #VALUE!
A38: 1104700010001 | B38: سيارة اسعاف صالون جمس | C38: ب ل ص 9475 | D38: 2005 | E38: رسمية - اصفر | F38: صالون | G38: 3GKFK16T05G272258 | H38: ادارة العمليات/الإدارة العامة للدفاع المدني بمحافظة جدة | I38: شعبة الدفاع المدني الميدانية بالإسكان الجنوبي | J38: شعبة الإسكان الجنوبي | K38: تم الاصلاح | M38: بطاريات | N38: 4-5-1447 | O38: 5-11-1447 | P38: شعبة الاسكان | Q38: مركز اسكان 1 ( الاسكان الجنوبي ) | S38: =IF( OR(K38="تم الاصلاح", O38<>""), "تم الاصلاح", IF(N38="", "", TODAY()-N38) ) -> تم الاصلاح
A39: 1106700020003 | B39: وايت سكس مرسيدس بمضخه وقاذف | C39: أ ن ب 3894 | D39: 2013 | E39: رسمية - اصفر | F39: صهريج سكس | G39: WDAKHAAA2DL713777 | H39: ادارة العمليات/الإدارة العامة للدفاع المدني بمحافظة جدة | I39: قسم الدعم والإسناد الثاني | J39: شعبة الحمدانية | K39: عطلانة | L39: أخرى | M39: كسر في الفلتر والرفرف | N39: 4-3-1447 | P39: شعبة الحمدانية | Q39: مركز شمال 5 ( ذهبان ) | R39: الاسناد | S39: =IF( OR(K39="تم الاصلاح", O39<>""), "تم الاصلاح", IF(N39="", "", TODAY()-N39) ) -> #VALUE!
A40: 1207700040006 | B40: سيارة رآس تريلا سكس مان | C40: ا ن د 4774 | D40: 2013 | E40: رسمية - اصفر | F40: تريلا | G40: WMA26WZZ6DM613818 | H40: ادارة العمليات/الإدارة العامة للدفاع المدني بمحافظة جدة | I40: قسم الدعم والإسناد الثاني | J40: مركز الدعم والاسناد الأول والثاني والثالث | K40: عطلانة | L40: ميكانيكي | M40: تهريب هواء من الباكم (الفرامل) | N40: 1-12-1447 | O40: 10-11-1447 | P40: قسم الاسناد الاول والثاني والثالث | S40: =IF( OR(K40="تم الاصلاح", O40<>""), "تم الاصلاح", IF(N40="", "", TODAY()-N40) ) -> تم الاصلاح
A41: 1204700010003 | B41: سيارة جيب 2 باب نيسان رسمي | C41: ا م ط 6540 | D41: 2006 | E41: رسمية - اصفر | F41: جيب | G41: JN8BY14Y06X525619 | H41: ادارة العمليات/الإدارة العامة للدفاع المدني بمحافظة جدة | I41: شعبة الدفاع المدني الميدانية بالإسكان الجنوبي | J41: شعبة الإسكان الجنوبي | K41: عطلانة | L41: ميكانيكي | M41: تهريب في ماء الرديتر | N41: 3-9-1446 | P41: شعبة الاسكان | Q41: مركز اسكان 1 ( الاسكان الجنوبي ) | S41: =IF( OR(K41="تم الاصلاح", O41<>""), "تم الاصلاح", IF(N41="", "", TODAY()-N41) ) -> #VALUE!
A42: 1106700010003 | B42: وايت عادي مرسيدس بمضخة وقاذف | C42: ا د م 2203 | D42: 1989 | E42: رسمية - اصفر | F42: صهريج عادي | G42: 34600155410132 | H42: ادارة العمليات/الإدارة العامة للدفاع المدني بمحافظة جدة | I42: شعبة الدفاع المدني الميدانية بالمروة | J42: شعبة المروة | K42: تم الاصلاح | L42: خلل فني | M42: تهريب هواء وثقل بالفرامل | N42: 22-9-1447 | O42: 17-1-1448 | P42: شعبة الحمدانية | Q42: مركز شمال 3 ( الرحيلي ) | S42: =IF( OR(K42="تم الاصلاح", O42<>""), "تم الاصلاح", IF(N42="", "", TODAY()-N42) ) -> تم الاصلاح
A43: 1201700020002 | B43: وايت ماء سقيا سكس مان | C43: ا ى ن 3852 | D43: 2015 | E43: رسمية - اصفر | F43: صهريج سكس (32) م2 | G43: RS076WZZXFD008481 | H43: ادارة العمليات/الإدارة العامة للدفاع المدني بمحافظة جدة | I43: قسم الدعم والإسناد الثالث | J43: شعبة أبحر | K43: عطلانة | L43: أخرى | M43: تهريب بلف الغطاس | N43: 3-4-1446 | P43: شعبة ابحر | Q43: مركز ابحر 1 ( ابحر الجنوبية ) | R43: الاسناد | S43: =IF( OR(K43="تم الاصلاح", O43<>""), "تم الاصلاح", IF(N43="", "", TODAY()-N43) ) -> #VALUE!
A44: 1204700010003 | B44: سيارة جيب 2 باب نيسان رسمي | C44: ا ل ع 1060 | D44: 2009 | E44: رسمية - اصفر | F44: جيب | G44: JN8BY14Y29X539588 | H44: ادارة العمليات/الإدارة العامة للدفاع المدني بمحافظة جدة | I44: شعبة الدفاع المدني الميدانية بالشاطئ | J44: شعبة الشاطئ | K44: تم الاصلاح | O44: 6-8-1447 | P44: شعبة الشاطئ | Q44: مركز غرب 1 ( الشاطئ ) | S44: =IF( OR(K44="تم الاصلاح", O44<>""), "تم الاصلاح", IF(N44="", "", TODAY()-N44) ) -> تم الاصلاح
A45: 1106700020003 | B45: وايت سكس مرسيدس بمضخه وقاذف | C45: ا ه س 6583 | D45: 2013 | E45: رسمية - اصفر | F45: صهريج سكس | G45: WDAKHAAA3DL772417 | H45: الدفاع المدني/مديرية منطقة مكة المكرمة/الإدارة العامة للدفاع المدني بمحافظة جدة | I45: مركز الدفاع المدني بالربوة | J45: شعبة المروة | K45: تم الاصلاح | O45: 13-8-1447 | P45: شعبة المروة | Q45: مركز صفا 3 ( الربوة ) | S45: =IF( OR(K45="تم الاصلاح", O45<>""), "تم الاصلاح", IF(N45="", "", TODAY()-N45) ) -> تم الاصلاح
A46: 1105700100001 | B46: سيارة فان افيكو رسمي للتجهيزات الفنية لوحدة الغواصين | C46: ب ا ح 2731 | D46: 2015 | E46: رسمية - اصفر | F46: فان | G46: ZCFC50AY6FD540305 | H46: ادارة العمليات/الإدارة العامة للدفاع المدني بمحافظة جدة | I46: قسم الدعم والإسناد الثالث | J46: شعبة البغدادية | K46: تم الاصلاح | O46: 13-8-1448 | P46: شعبة البغدادية | Q46: مركز بلد 1 ( الحمراء ) | S46: =IF( OR(K46="تم الاصلاح", O46<>""), "تم الاصلاح", IF(N46="", "", TODAY()-N46) ) -> تم الاصلاح
A47: 1106700020003 | B47: وايت سكس مرسيدس بمضخه وقاذف | C47: ا ن ط 2479 | D47: 2013 | E47: رسمية - اصفر | F47: صهريج سكس | G47: WDAKHAAA9DL719091 | H47: الدفاع المدني/مديرية منطقة مكة المكرمة/الإدارة العامة للدفاع المدني بمحافظة جدة | I47: مركز الدفاع المدني بالمروة | J47: شعبة المروة | K47: تم الاصلاح | L47: ميكانيكي | M47: تهريب هواء | N47: 30-3-1447 | O47: 22-1-1448 | P47: شعبة المروة | Q47: مركز صفا 5 ( الفيصلية ) | S47: =IF( OR(K47="تم الاصلاح", O47<>""), "تم الاصلاح", IF(N47="", "", TODAY()-N47) ) -> تم الاصلاح
A48: 1104700020001 | B48: سيارة اسعاف فان جمس | C48: ا ه ب 4251 | D48: 2012 | E48: رسمية - اصفر وابيض | F48: فان | G48: 1GTW78CG0C1193679 | H48: ادارة العمليات/الإدارة العامة للدفاع المدني بمحافظة جدة | I48: شعبة الدفاع المدني الميدانية بالعزيزية | J48: شعبة العزيزية | K48: عطلانة | L48: كهربائي | M48: التماس كهربائي في الكابينة | N48: 30-1-1447 | P48: شعبة العزيزية | Q48: مركز وسط 1 ( الرحاب ) | S48: =IF( OR(K48="تم الاصلاح", O48<>""), "تم الاصلاح", IF(N48="", "", TODAY()-N48) ) -> #VALUE!
...

Sheet قاعدة البيانات
B1: رقم الصنف | C1: نوع السيارة تفصيلي | D1: رقم اللوحة كامل | E1: الاجراء حسب الصيانة المركزية | F1: الموديل | G1: اللون | H1: نوع السيارة عام | I1: رقم الشاصية | J1: الجهة عام | K1: الجهة تفصيلي (تنطيق الاوراكل) | L1: الموقع الالية الحالي | M1: الحالة الفنية | N1: نوع العطل | O1: وصف العطل | P1: تاريخ العطل | Q1: تاريخ الإصلاح | R1: ملاحظات | S1: جهة العطل | T1: صالحة | U1: شعبة الحمدانية | V1: ميكانيكي | X1: شمال 1 | Y1: تعمل | Z1: التسليم وتحرك الالية
A2: 294 | B2: 1112700020001 | C2: تيدر نقل محروقات صناعه وطنيه | D2: ا ك ل 2362 | F2: 2011 | G2: رسمية - اصفر | H2: شاحنة | I2: JAMLP3457B7P02403 | J2: ادارة العمليات/الإدارة العامة للدفاع المدني بمحافظة جدة | K2: قسم الدعم والإسناد الأول | L2: مركز الدعم والاسناد الأول والثاني والثالث | M2: عطلانة | N2: ميكانيكي | O2: الدسك والصحن والحذاف | P2: 25-12-1447 | R2: قاطرة المحروقات الاسناد | S2: قسم الاسناد الاول والثاني والثالث
A3: 291 | B3: 1109700010001 | C3: جرافة تركتر كبير | D3: ا س ق 2410 | E3: جاري العمل على الإصلاح | F3: 1976 | G3: رسمية - اصفر | H3: تريكتر | I3: 48W14586 | J3: ادارة العمليات/الإدارة العامة للدفاع المدني بمحافظة جدة | K3: قسم الدعم والإسناد الأول | L3: مركز الدعم والاسناد الأول والثاني والثالث | M3: عطلانة | N3: ميكانيكي | O3: مسامير الجنزير | P3: 20-8-1447 | S3: قسم الاسناد الاول والثاني والثالث
A4: 292 | B4: 1110700010001 | C4: حفار ودقاق بوكلين | D4: ا ب ح 6452 | F4: 2006 | G4: رسمية - اصفر | H4: شيول | I4: 200L35354 | J4: ادارة العمليات/الإدارة العامة للدفاع المدني بمحافظة جدة | K4: قسم الدعم والإسناد الأول | L4: مركز الدعم والاسناد الأول والثاني والثالث | M4: تعمل
A5: 293 | B5: 1111700030001 | C5: حواس | D5: ا ق ى 7559 | F5: 2006 | G5: رسمية - اصفر | H5: شيول | I5: N6M430345 | J5: ادارة العمليات/الإدارة العامة للدفاع المدني بمحافظة جدة | K5: قسم الدعم والإسناد الأول | L5: مركز الدعم والاسناد الأول والثاني والثالث | M5: تعمل
A6: 480 | B6: 1306700020001 | C6: دراجة نارية (4*4) للبحث والانقاذ | D6: بدون | F6: بدون | G6: غير مخصصة | H6: لم يسجل | I6: JKAVFDG14FB508540 | J6: المديرية العامة للدفاع المدني للمواسم/الدفاع المدني/مديرية منطقة مكة المكرمة | K6: مركز السلامة الميدانية بالشاطئ | L6: شعبة الشاطئ | M6: عطلانة | N6: أخرى | O6: تحتاج الى صيانة | P6: 1-9-1447 | R6: تاريخ ادارج العطل وليس تاريخ العطل نفسه
A7: 481 | B7: 1306700020001 | C7: دراجة نارية (4*4) للبحث والانقاذ | D7: بدون | F7: بدون | G7: غير مخصصة | H7: لم يسجل | I7: JKAVFDG19FB508551 | J7: المديرية العامة للدفاع المدني للمواسم/الدفاع المدني/مديرية منطقة مكة المكرمة | K7: مركز السلامة الميدانية بالشاطئ | L7: شعبة الشاطئ | M7: عطلانة | N7: أخرى | O7: تحتاج الى صيانة | P7: 1-9-1447 | R7: تاريخ ادارج العطل وليس تاريخ العطل نفسه
A8: 518 | B8: 1306700010002 | C8: دراجة نارية ذات 4 كفرات مزودة بجهاز اطفاء بالرغوة كبير | D8: بدون | F8: 2013 | G8: رسمية - اصفر | H8: دراجة نارية | I8: WR9KLM1PN3MX | J8: المديرية العامة للدفاع المدني للمواسم/الدفاع المدني/مديرية منطقة مكة المكرمة | K8: مركز السلامة الميدانية بالبغدادية | L8: شعبة البغدادية | M8: عطلانة | N8: أخرى | O8: تحتاج الى صيانة | P8: 1-9-1447 | R8: تاريخ ادارج العطل وليس تاريخ العطل نفسه
A9: 461 | B9: 1306700010002 | C9: دراجة نارية ذات 4 كفرات مزودة بجهاز اطفاء بالرغوة كبير | D9: بدون | F9: 2013 | G9: رسمية - اصفر | H9: دراجة نارية | I9: WR9KLM1PN3MH | J9: المديرية العامة للدفاع المدني للمواسم/الدفاع المدني/مديرية منطقة مكة المكرمة | K9: مركز السلامة الميدانية بأبحر | L9: شعبة أبحر | M9: عطلانة | N9: أخرى | O9: تحتاج الى صيانة | P9: 1-9-1447 | R9: تاريخ ادارج العطل وليس تاريخ العطل نفسه
A10: 517 | B10: 1306700010001 | C10: دراجة نارية مزودة بجهاز اطفاء بالرغوة يدوي متنقل نوع BMW | D10: ه ح 565 | F10: 2012 | G10: رسمية - اصفر | H10: دراجة نارية | I10: WB104300XCZW46665 | J10: المديرية العامة للدفاع المدني للمواسم/الدفاع المدني/مديرية منطقة مكة المكرمة | K10: مركز السلامة الميدانية بالبغدادية | L10: شعبة البغدادية | M10: عطلانة | N10: أخرى | O10: تحتاج الى صيانة | P10: 1-9-1447 | R10: تاريخ ادارج العطل وليس تاريخ العطل نفسه
A11: 460 | B11: 1306700010001 | C11: دراجة نارية مزودة بجهاز اطفاء بالرغوة يدوي متنقل نوع BMW | D11: ه ح 564 | F11: 2012 | G11: رسمية - اصفر | H11: دراجة نارية | I11: WB104300CZW52145 | J11: المديرية العامة للدفاع المدني للمواسم/الدفاع المدني/مديرية منطقة مكة المكرمة | K11: مركز السلامة الميدانية بأبحر | L11: شعبة أبحر | M11: عطلانة | N11: أخرى | O11: تحتاج الى صيانة | P11: 1-9-1447 | R11: تاريخ ادارج العطل وليس تاريخ العطل نفسه
A12: 13 | B12: 1303700010001 | C12: دراجة نارية ياماها 250 | D12: ص ا 661 | F12: 2010 | G12: رسمية - اخضر | H12: دراجة نارية | I12: JYA4TN00000014030 | J12: ادارة العمليات/الإدارة العامة للدفاع المدني بمحافظة جدة | K12: قسم الدعم والإسناد الأول | L12: مركز الدعم والاسناد الأول والثاني والثالث | M12: تم الإصلاح | Q12: 3-8-1447 | S12: قسم الاسناد الاول والثاني والثالث | X12: غرب 4
A13: 507 | B13: 1303700010001 | C13: دراجة نارية ياماها 250 | D13: ص ا 159 | F13: 2010 | G13: رسمية - اخضر | H13: دراجة نارية | I13: JYA4TN00000014185 | J13: المديرية العامة للدفاع المدني للمواسم/الدفاع المدني/مديرية منطقة مكة المكرمة | K13: مركز السلامة الميدانية بالإسكان الجنوبي | L13: شعبة الإسكان الجنوبي | M13: عطلانة | N13: أخرى | O13: تحتاج الى صيانة | P13: 1-9-1447 | R13: تاريخ ادارج العطل وليس تاريخ العطل نفسه
A14: 508 | B14: 1303700010001 | C14: دراجة نارية ياماها 250 | D14: ح ح 919 | F14: 2011 | G14: رسمية - اخضر | H14: دراجة نارية | I14: JYA4TN0073A014493 | J14: المديرية العامة للدفاع المدني للمواسم/الدفاع المدني/مديرية منطقة مكة المكرمة | K14: مركز السلامة الميدانية بالإسكان الجنوبي | L14: شعبة الإسكان الجنوبي | M14: عطلانة | N14: أخرى | O14: تحتاج الى صيانة | P14: 1-9-1447 | R14: تاريخ ادارج العطل وليس تاريخ العطل نفسه
A15: 509 | B15: 1303700010001 | C15: دراجة نارية ياماها 250 | D15: ح ح 654 | F15: 2011 | G15: رسمية - اخضر | H15: دراجة نارية | I15: JYA4TN00X3A014567 | J15: المديرية العامة للدفاع المدني للمواسم/الدفاع المدني/مديرية منطقة مكة المكرمة | K15: مركز السلامة الميدانية بالإسكان الجنوبي | L15: شعبة الإسكان الجنوبي | M15: عطلانة | N15: أخرى | O15: تحتاج الى صيانة | P15: 1-9-1447 | R15: تاريخ ادارج العطل وليس تاريخ العطل نفسه
A16: 516 | B16: 1303700010001 | C16: دراجة نارية ياماها 250 | D16: ق ب 605 | F16: 2010 | G16: رسمية - اخضر | H16: دراجة نارية | I16: JYA4TN00000014064 | J16: المديرية العامة للدفاع المدني للمواسم/الدفاع المدني/مديرية منطقة مكة المكرمة | K16: مركز السلامة الميدانية بالبغدادية | L16: شعبة البغدادية | M16: عطلانة | N16: أخرى | O16: تحتاج الى صيانة | P16: 1-9-1447 | R16: تاريخ ادارج العطل وليس تاريخ العطل نفسه
A17: 498 | B17: 1303700010001 | C17: دراجة نارية ياماها 250 | D17: ق ب 615 | F17: 2010 | G17: رسمية - اخضر | H17: دراجة نارية | I17: JYA4TN00000014032 | J17: المديرية العامة للدفاع المدني للمواسم/الدفاع المدني/مديرية منطقة مكة المكرمة | K17: مركز السلامة الميدانية بالجامعة | L17: شعبة الجامعة | M17: عطلانة | N17: أخرى | O17: تحتاج الى صيانة | P17: 1-9-1447 | R17: تاريخ ادارج العطل وليس تاريخ العطل نفسه
A18: 499 | B18: 1303700010001 | C18: دراجة نارية ياماها 250 | D18: ق ب 613 | F18: 2010 | G18: رسمية - اخضر | H18: دراجة نارية | I18: JYA4TN00000014052 | J18: المديرية العامة للدفاع المدني للمواسم/الدفاع المدني/مديرية منطقة مكة المكرمة | K18: مركز السلامة الميدانية بالجامعة | L18: شعبة الجامعة | M18: عطلانة | N18: أخرى | O18: تحتاج الى صيانة | P18: 1-9-1447 | R18: تاريخ ادارج العطل وليس تاريخ العطل نفسه
A19: 500 | B19: 1303700010001 | C19: دراجة نارية ياماها 250 | D19: ص ا 647 | F19: 2010 | G19: رسمية - اخضر | H19: دراجة نارية | I19: JYA4TN00000014145 | J19: المديرية العامة للدفاع المدني للمواسم/الدفاع المدني/مديرية منطقة مكة المكرمة | K19: مركز السلامة الميدانية بالجامعة | L19: شعبة الجامعة | M19: عطلانة | N19: أخرى | O19: تحتاج الى صيانة | P19: 1-9-1447 | R19: تاريخ ادارج العطل وليس تاريخ العطل نفسه
A20: 468 | B20: 1303700010001 | C20: دراجة نارية ياماها 250 | D20: ص ا 194 | F20: 2010 | G20: رسمية - اخضر | H20: دراجة نارية | I20: JYA4TN00000014036 | J20: المديرية العامة للدفاع المدني للمواسم/الدفاع المدني/مديرية منطقة مكة المكرمة | K20: مركز السلامة الميدانية بالحمدانية | L20: شعبة الحمدانية | M20: عطلانة | N20: أخرى | O20: تحتاج الى صيانة | P20: 1-9-1447 | R20: تاريخ ادارج العطل وليس تاريخ العطل نفسه
A21: 469 | B21: 1303700010001 | C21: دراجة نارية ياماها 250 | D21: ق ب 688 | F21: 2010 | G21: رسمية - اخضر | H21: دراجة نارية | I21: JYA4TN00000014152 | J21: المديرية العامة للدفاع المدني للمواسم/الدفاع المدني/مديرية منطقة مكة المكرمة | K21: مركز السلامة الميدانية بالحمدانية | L21: شعبة الحمدانية | M21: عطلانة | N21: أخرى | O21: تحتاج الى صيانة | P21: 1-9-1447 | R21: تاريخ ادارج العطل وليس تاريخ العطل نفسه
A22: 532 | B22: 1303700010001 | C22: دراجة نارية ياماها 250 | D22: ص ا 238 | F22: 2010 | G22: رسمية - اخضر | H22: دراجة نارية | I22: JYA4TN00000014207 | J22: المديرية العامة للدفاع المدني للمواسم/الدفاع المدني/مديرية منطقة مكة المكرمة | K22: مركز السلامة الميدانية بالصناعية | L22: الصيانة المركزية | M22: تم الاصلاح | Q22: 8-9-1447 | R22: طلبت للصيانة بتاريخ 6-2-1448 ولم ترفع متعطله
A23: 470 | B23: 1303700010001 | C23: دراجة نارية ياماها 250 | D23: ص ا 133 | F23: 2010 | G23: رسمية - اخضر | H23: دراجة نارية | I23: JYA4TN00000014272 | J23: المديرية العامة للدفاع المدني للمواسم/الدفاع المدني/مديرية منطقة مكة المكرمة | K23: مركز السلامة الميدانية بالحمدانية | L23: شعبة الحمدانية | M23: عطلانة | N23: أخرى | O23: تحتاج الى صيانة | P23: 1-9-1447 | R23: تاريخ ادارج العطل وليس تاريخ العطل نفسه
A24: 524 | B24: 1303700010001 | C24: دراجة نارية ياماها 250 | D24: ص ا 179 | F24: 2010 | G24: رسمية - اخضر | H24: دراجة نارية | I24: JYA4TN00000014225 | J24: المديرية العامة للدفاع المدني للمواسم/الدفاع المدني/مديرية منطقة مكة المكرمة | K24: مركز السلامة الميدانية بالخزام | L24: شعبة خزام | M24: عطلانة | N24: أخرى | O24: تحتاج الى صيانة | P24: 1-9-1447 | R24: تاريخ ادارج العطل وليس تاريخ العطل نفسه
A25: 525 | B25: 1303700010001 | C25: دراجة نارية ياماها 250 | D25: ق ب 678 | F25: 2010 | G25: رسمية - اخضر | H25: دراجة نارية | I25: JYA4TN00000014301 | J25: المديرية العامة للدفاع المدني للمواسم/الدفاع المدني/مديرية منطقة مكة المكرمة | K25: مركز السلامة الميدانية بالخزام | L25: شعبة خزام | M25: عطلانة | N25: أخرى | O25: تحتاج الى صيانة | P25: 1-9-1447 | R25: تاريخ ادارج العطل وليس تاريخ العطل نفسه
A26: 526 | B26: 1303700010001 | C26: دراجة نارية ياماها 250 | D26: ق ب 639 | F26: 2010 | G26: رسمية - اخضر | H26: دراجة نارية | I26: JYA4TN00000014302 | J26: المديرية العامة للدفاع المدني للمواسم/الدفاع المدني/مديرية منطقة مكة المكرمة | K26: مركز السلامة الميدانية بالخزام | L26: شعبة خزام | M26: عطلانة | N26: أخرى | O26: تحتاج الى صيانة | P26: 1-9-1447 | R26: تاريخ ادارج العطل وليس تاريخ العطل نفسه
A27: 540 | B27: 1303700010001 | C27: دراجة نارية ياماها 250 | D27: ص ا 178 | F27: 2010 | G27: رسمية - اخضر | H27: دراجة نارية | I27: JYA4TN00000014182 | J27: المديرية العامة للدفاع المدني للمواسم/الدفاع المدني/مديرية منطقة مكة المكرمة | K27: مركز السلامة الميدانية بالساحل الجنوبي | L27: الصيانة المركزية | M27: عطلانة | N27: أخرى | O27: تحتاج الى صيانة | P27: 1-9-1447 | R27: تاريخ ادارج العطل وليس تاريخ العطل نفسه
A28: 541 | B28: 1303700010001 | C28: دراجة نارية ياماها 250 | D28: ص ا 156 | F28: 2010 | G28: رسمية - اخضر | H28: دراجة نارية | I28: JYA4TN00000014210 | J28: المديرية العامة للدفاع المدني للمواسم/الدفاع المدني/مديرية منطقة مكة المكرمة | K28: مركز السلامة الميدانية بالساحل الجنوبي | L28: الصيانة المركزية | M28: عطلانة | N28: أخرى | O28: تحتاج الى صيانة | P28: 1-9-1447 | R28: تاريخ ادارج العطل وليس تاريخ العطل نفسه
A29: 542 | B29: 1303700010001 | C29: دراجة نارية ياماها 250 | D29: ص ا 175 | F29: 2010 | G29: رسمية - اخضر | H29: دراجة نارية | I29: JYA4TN00000014215 | J29: المديرية العامة للدفاع المدني للمواسم/الدفاع المدني/مديرية منطقة مكة المكرمة | K29: مركز السلامة الميدانية بالساحل الجنوبي | L29: الصيانة المركزية | M29: عطلانة | N29: أخرى | O29: تحتاج الى صيانة | P29: 1-9-1447 | R29: تاريخ ادارج العطل وليس تاريخ العطل نفسه | Z29: مركز ثول
A30: 548 | B30: 1303700010001 | C30: دراجة نارية ياماها 250 | D30: ق ب 628 | F30: 2010 | G30: رسمية - اخضر | H30: دراجة نارية | I30: JYA4TN00000014283 | J30: المديرية العامة للدفاع المدني للمواسم/الدفاع المدني/مديرية منطقة مكة المكرمة | K30: مركز السلامة الميدانية بالسالمية | L30: شعبة السالمية | M30: عطلانة | N30: أخرى | O30: تحتاج الى صيانة | P30: 1-9-1447 | R30: تاريخ ادارج العطل وليس تاريخ العطل نفسه
A31: 549 | B31: 1303700010001 | C31: دراجة نارية ياماها 250 | D31: ص ا 605 | F31: 2010 | G31: رسمية - اخضر | H31: دراجة نارية | I31: JYA4TN0000013903 | J31: المديرية العامة للدفاع المدني للمواسم/الدفاع المدني/مديرية منطقة مكة المكرمة | K31: مركز السلامة الميدانية بالسالمية | L31: شعبة السالمية | M31: عطلانة | N31: أخرى | O31: تحتاج الى صيانة | P31: 1-9-1447 | R31: تاريخ ادارج العطل وليس تاريخ العطل نفسه
A32: 550 | B32: 1303700010001 | C32: دراجة نارية ياماها 250 | D32: ه ب 769 | F32: 2011 | G32: رسمية - اخضر | H32: دراجة نارية | I32: JYA4TN0013A014392 | J32: المديرية العامة للدفاع المدني للمواسم/الدفاع المدني/مديرية منطقة مكة المكرمة | K32: مركز السلامة الميدانية بالسالمية | L32: شعبة السالمية | M32: عطلانة | N32: أخرى | O32: تحتاج الى صيانة | P32: 1-9-1447 | R32: تاريخ ادارج العطل وليس تاريخ العطل نفسه
A33: 478 | B33: 1303700010001 | C33: دراجة نارية ياماها 250 | D33: ص ا 263 | F33: 2010 | G33: رسمية - اخضر | H33: دراجة نارية | I33: JYA4TN00000014227 | J33: المديرية العامة للدفاع المدني للمواسم/الدفاع المدني/مديرية منطقة مكة المكرمة | K33: مركز السلامة الميدانية بالشاطئ | L33: شعبة الشاطئ | M33: عطلانة | N33: أخرى | O33: تحتاج الى صيانة | P33: 1-9-1447 | R33: تاريخ ادارج العطل وليس تاريخ العطل نفسه
A34: 479 | B34: 1303700010001 | C34: دراجة نارية ياماها 250 | D34: ق ب 657 | F34: 2010 | G34: رسمية - اخضر | H34: دراجة نارية | I34: JYA4TN00000014279 | J34: المديرية العامة للدفاع المدني للمواسم/الدفاع المدني/مديرية منطقة مكة المكرمة | K34: مركز السلامة الميدانية بالشاطئ | L34: شعبة الشاطئ | M34: عطلانة | N34: أخرى | O34: تحتاج الى صيانة | P34: 1-9-1447 | R34: تاريخ ادارج العطل وليس تاريخ العطل نفسه | Z34: شعبة السالمية
A35: 533 | B35: 1303700010001 | C35: دراجة نارية ياماها 250 | D35: ه ب 723 | F35: 2011 | G35: رسمية - اخضر | H35: دراجة نارية | I35: JYA4TN0033A014572 | J35: المديرية العامة للدفاع المدني للمواسم/الدفاع المدني/مديرية منطقة مكة المكرمة | K35: مركز السلامة الميدانية بالصناعية | L35: الصيانة المركزية | M35: عطلانة | N35: أخرى | O35: تحتاج الى صيانة | P35: 1-9-1447 | R35: تاريخ ادارج العطل وليس تاريخ العطل نفسه
A36: 489 | B36: 1303700010001 | C36: دراجة نارية ياماها 250 | D36: ص ا 451 | F36: 2010 | G36: رسمية - اخضر | H36: دراجة نارية | I36: JYA4TN00000013926 | J36: المديرية العامة للدفاع المدني للمواسم/الدفاع المدني/مديرية منطقة مكة المكرمة | K36: مركز السلامة الميدانية بالعزيزية | L36: شعبة العزيزية | M36: عطلانة | N36: أخرى | O36: تحتاج الى صيانة | P36: 1-9-1447 | R36: تاريخ ادارج العطل وليس تاريخ العطل نفسه
A37: 490 | B37: 1303700010001 | C37: دراجة نارية ياماها 250 | D37: ق ب 670 | F37: 2010 | G37: رسمية - اخضر | H37: دراجة نارية | I37: JYA4TN00000014123 | J37: المديرية العامة للدفاع المدني للمواسم/الدفاع المدني/مديرية منطقة مكة المكرمة | K37: مركز السلامة الميدانية بالعزيزية | L37: شعبة العزيزية | M37: عطلانة | N37: أخرى | O37: تحتاج الى صيانة | P37: 1-9-1447 | R37: تاريخ ادارج العطل وليس تاريخ العطل نفسه
A38: 491 | B38: 1303700010001 | C38: دراجة نارية ياماها 250 | D38: ق ب 675 | F38: 2010 | G38: رسمية - اخضر | H38: دراجة نارية | I38: JYA4TN00000014161 | J38: المديرية العامة للدفاع المدني للمواسم/الدفاع المدني/مديرية منطقة مكة المكرمة | K38: مركز السلامة الميدانية بالعزيزية | L38: شعبة العزيزية | M38: عطلانة | N38: أخرى | O38: تحتاج الى صيانة | P38: 1-9-1447 | R38: تاريخ ادارج العطل وليس تاريخ العطل نفسه | Z38: تم تسليمه للاسناد من وسط 5
A39: 444 | B39: 1303700010001 | C39: دراجة نارية ياماها 250 | D39: ص ا 286 | F39: 2010 | G39: رسمية - اخضر | H39: دراجة نارية | I39: JYA4TN00000014139 | J39: المديرية العامة للدفاع المدني للمواسم/الدفاع المدني/مديرية منطقة مكة المكرمة | K39: مركز السلامة الميدانية بالمروة | L39: شعبة المروة | M39: عطلانة | N39: أخرى | O39: تحتاج الى صيانة | P39: 1-9-1447 | R39: تاريخ ادارج العطل وليس تاريخ العطل نفسه
A40: 445 | B40: 1303700010001 | C40: دراجة نارية ياماها 250 | D40: ق ب 579 | F40: 2010 | G40: رسمية - اخضر | H40: دراجة نارية | I40: JYA4TN00000014297 | J40: المديرية العامة للدفاع المدني للمواسم/الدفاع المدني/مديرية منطقة مكة المكرمة | K40: مركز السلامة الميدانية بالمروة | L40: شعبة المروة | M40: عطلانة | N40: أخرى | O40: تحتاج الى صيانة | P40: 1-9-1447 | R40: تاريخ ادارج العطل وليس تاريخ العطل نفسه
...

Sheet الاعدادت
B1: الموقع الالية الحالي | C1: الحالة الفنية | D1: نوع العطل
B2: شعبة الحمدانية | C2: عطلانة | D2: ميكانيكي | F2: شعبة الشاطئ | G2: شعبة الحمدانية | H2: شعبة العزيزية | I2: شعبة المروة | J2: شعبة ابحر | K2: شعبة السالمية | L2: شعبة الجامعة | M2: شعبة الصناعية | N2: شعبة خزام | O2: شعبة البغدادية | P2: شعبة الساحل الجنوبي | Q2: شعبة الاسكان | R2: مركز ثول الخارجي | S2: قسم الاسناد الاول والثاني والثالث
B3: شعبة أبحر / مركز درة العروس | C3: تم الاصلاح | D3: بطاريات | F3: مركز غرب 1 ( الشاطئ ) | G3: مركز شمال 1 ( الحمدانية ) | H3: مركز وسط 1 ( الرحاب ) | I3: مركز صفا 1 ( المروة ) | J3: مركز ابحر 1 ( ابحر الجنوبية ) | K3: مركز سالمية 1 ( السالمية ) | L3: مركز شرق 1 ( الجامعة ) | M3: مركز صناعية 1 ( الصناعية ) | N3: مركز خزام 1 ( خزام ) | O3: مركز بلد 1 ( الحمراء ) | P3: مركز جنوب 1 ( الكورنيش ) | Q3: مركز اسكان 1 ( الاسكان الجنوبي ) | R3: مركز ثول
B4: شعبة الاسكان / مركز الحرازات الشرقي | C4: تحت إجراءات الرجيع | D4: كهربائي | F4: مركز غرب 2 ( الخالدية ) | G4: مركز شمال 2 ( بريمان ) | H4: مركز وسط 2 ( العزيزية ) | I4: مركز صفا 2 ( النزهة ) | J4: مركز ابحر 2 ( ابحر الشمالية ) | K4: مركز سالمية 2 ( النخيل ) | L4: مركز شرق 2 ( الروابي ) | M4: مركز صناعية 2 ( المرحلة الاولى ) | N4: مركز خزام 2 ( مدائن الفهد ) | O4: مركز بلد 2 ( البغدادية ) | P4: مركز جنوب 2 ( الصناعية الثانية ) | Q4: مركز اسكان 2 ( ام السلم ) | R4: مركز مجد 2 ( الجزيرة )
B5: شعبة الصناعية | C5: صدر قرار الرجيع | D5: مضخات | F5: مركز غرب 3 ( الروضة ) | G5: مركز شمال 3 ( الرحيلي ) | H5: مركز وسط 3 ( النسيم ) | I5: مركز صفا 3 ( الربوة ) | J5: مركز ابحر 3 ( المحمدية ) | K5: مركز سالمية 3 | L5: مركز شرق 3 ( قويزة ) | M5: مركز صناعية 3 ( الاسواق الشعبية ) | N5: مركز خزام 3 ( الكندرة ) | O5: مركز بلد 3 ( باب مكة ) | P5: مركز جنوب 3 ( طريق الساحل ) | Q5: مركز اسكان 3 ( الالفية )
B6: شعبة الساحل / مركز الكورنيش الجنوبي | C6: تعمل بوجود ملاحظات | D6: أخرى | F6: مركز غرب 4 ( النهضة ) | G6: مركز شمال 4 ( الرياض ) | H6: مركز وسط 4 ( بني مالك ) | I6: مركز صفا 4 ( الصفا ) | J6: مركز ابحر 4 ( درة العروس ) | K6: مركز سالمية 4 ( السامر ) | L6: مركز شرق 4 ( المنتزهات ) | M6: مركز صناعية 5 ( السنابل ) | N6: مركز خزام 4 ( المصفاة ) | O6: مركز بلد 4 ( الخاسكية ) | P6: مركز جنوب 4 ( الخمرة ) | Q6: مركز اسكان 4 ( الحزرات الشرقي )
B7: شعبة السالمية | C7: تعمل | D7: برمجة | F7: مركز مجد 1 ( قصر السلام ) | G7: مركز شمال 5 ( ذهبان ) | H7: مركز وسط 5 ( الاندلس ) | I7: مركز صفا 5 ( الفيصلية ) | K7: مركز سالمية 5 ( المنار ) | L7: مركز شرق 5 ( الحرزات الشمالي ) | N7: مركز بترومين | O7: مركز بلد 5 ( الشرفية ) | P7: مركز جنوب 5 ( المستودعات ) | Q7: مركز اسكان 5 ( المحاميد )
B8: شعبة أبحر / مركز أبحر الشمالية | C8: تحت التجهيز والتسليم | D8: كفرات | F8: مركز مجد 3
B9: شعبة خزام / مركز بترومين | D9: خلل فني | F9: مركز مجد 3ب
B10: شعبة البغدادية / مركز إسكان الشرفية | D10: تجديد ودهان
B11: شعبة الصناعية / مركز المرحلة الأولى | D11: حادث مروري
B12: شعبة البغدادية / مركز البغدادية
B13: الصيانة المركزية
B14: شعبة السالمية / مركز المنار | H14: قسم الاسناد الاول والثاني والثالث | J14: جاري العمل على الإصلاح | M14: ادارة العمليات | N14: جميع الجهات من غير تكرار
B15: شعبة الشاطئ / مركز النهضة | H15: شعبة الشاطئ | J15: بانتظار ترسية المنافسة | M15: المكتب
B16: شعبة السالمية / مركز السامر | H16: مركز غرب 1 ( الشاطئ ) | J16: غير مدرج في بيان الأعطال | M16: إدارة السلامة
B17: شعبة الشاطئ / مركز حي السلامة | H17: مركز غرب 2 ( الخالدية ) | J17: إجراءات الإحالة للرجيع | M17: إدارة الشؤون الإدارية
B18: شعبة الجامعة / مركز الروابي | H18: مركز غرب 3 ( الروضة ) | J18: تم الإصلاح وبحاجة تشخيص جديد | M18: شعبة التحقيق
B19: شعبة الصناعية / مركز الصناعية الثانية | H19: مركز غرب 4 ( النهضة ) | J19: تم الإصلاح | M19: شعبة التموين والمستودعات
B20: شعبة العزيزية / مركز حي مشرفة | H20: مركز مجد 1 ( قصر السلام ) | J20: جاري الكشف والتشخيص | M20: شعبة الدفاع المدني الميدانية بالإسكان الجنوبي
B21: شعبة البغدادية | H21: مركز مجد 3 | J21: إجراءات الامر المستديم 198 | M21: شعبة الدفاع المدني الميدانية بالبغدادية
B22: شعبة السالمية / مركز التيسير | H22: مركز مجد 3ب | M22: شعبة الدفاع المدني الميدانية بالجامعة
B23: شعبة المروة | H23: شعبة الحمدانية | M23: شعبة الدفاع المدني الميدانية بالحمدانية
B24: شعبة المروة / مركز الفيصلية | H24: مركز شمال 1 ( الحمدانية ) | M24: شعبة الدفاع المدني الميدانية بالخزام
B25: مركز ثول | H25: مركز شمال 2 ( بريمان ) | M25: شعبة الدفاع المدني الميدانية بالساحل الجنوبي
B26: ورشة خارجية | H26: مركز شمال 3 ( الرحيلي ) | M26: شعبة الدفاع المدني الميدانية بالسالمية
B27: شعبة الجامعة | H27: مركز شمال 4 ( الرياض ) | M27: شعبة الدفاع المدني الميدانية بالشاطئ
B28: شعبة الساحل / مركز طريق الساحل | H28: مركز شمال 5 ( ذهبان ) | M28: شعبة الدفاع المدني الميدانية بالصناعية
B29: شعبة الصناعية / مركز الأسواق الشعبية | H29: شعبة العزيزية | M29: شعبة الدفاع المدني الميدانية بالعزيزية
B30: شعبة الاسكان / مركز الألفية | H30: مركز وسط 1 ( الرحاب ) | M30: شعبة الدفاع المدني الميدانية بالمروة
B31: شعبة الحمدانية / مركز الحمدانية | H31: مركز وسط 2 ( العزيزية ) | M31: شعبة الدفاع المدني الميدانية بأبحر
B32: شعبة الحمدانية / مركز مخطط الرحيلي | H32: مركز وسط 3 ( النسيم ) | M32: شعبة الشؤون الفنية
B33: شعبة الحمدانية / مركز بريمان | H33: مركز وسط 4 ( بني مالك ) | M33: شعبة المراجعة الداخلية
... B85: ش روزنباور | H85: مركز اسكان 4 ( الحزرات الشرقي ) | M85: مركز الدفاع المدني بحى المنار
H86: مركز اسكان 5 ( المحاميد ) | M86: مركز الدفاع المدني بحى النخيل
H87: مركز ثول الخارجي | M87: مركز الدفاع المدني بحى بني مالك
H88: مركز ثول | M88: مركز الدفاع المدني بحي البوادي
H89: مركز مجد 2 ( الجزيرة ) | M89: مركز الدفاع المدني بحي التيسير
M90: مركز الدفاع المدني بحي الرياض
M91: مركز الدفاع المدني بحي السلامة
...

Sheet قوائم منسدلة
A1: السنة | B1: الشهر | C1: الأسبوع | D1: اليوم | I1: عطلانة | J1: تم الاصلاح | K1: تحت إجراءات الرجيع | L1: صدر قرار الرجيع | M1: ميكانيكي | N1: بطاريات | O1: كهربائي | P1: مضخات | Q1: أخرى | R1: برمجة | S1: كفرات | T1: خلل فني | U1: تجديد ودهان | V1: حادث مروري
A2: الكل | B2: الكل | C2: الكل | D2: الكل | I2: =COUNTIF('لوحة التحكم'!K13:K1048576,"عطلانة") -> 199 | J2: =COUNTIF('لوحة التحكم'!K13:K1048576,"تم الاصلاح") -> 168 | K2: =COUNTIF('لوحة التحكم'!K13:K1048576,"تحت إجراءات الرجيع") -> 23 | L2: =COUNTIF('لوحة التحكم'!K13:K1048576,"صدر قرار الرجيع") -> 58 | M2: =COUNTIF('لوحة التحكم'!L13:L1048576,"ميكانيكي") -> 100 | N2: =COUNTIF('لوحة التحكم'!L13:L1048576,"بطاريات") -> 8 | O2: =COUNTIF('لوحة التحكم'!L13:L1048576,"كهربائي") -> 21 | P2: =COUNTIF('لوحة التحكم'!L13:L1048576,"مضخات") -> 11 | Q2: =COUNTIF('لوحة التحكم'!L13:L1048576,"أخرى") -> 156 | R2: =COUNTIF('لوحة التحكم'!L13:L1048576,"برمجة") -> 1 | S2: =COUNTIF('لوحة التحكم'!L13:L1048576,"كفرات") -> 10 | T2: =COUNTIF('لوحة التحكم'!L13:L1048576,"خلل فني") -> 42 | U2: =COUNTIF('لوحة التحكم'!L13:L1048576,"تجديد ودهان") -> 2 | V2: =COUNTIF('لوحة التحكم'!L13:L1048576,"حادث مروري") -> 16
A3: 2025 | B3: 1 | C3: 1 | D3: 1
A4: 2026 | B4: 2 | C4: 2 | D4: 2
